<?xml version="1.0"?>
<robot name="navbot_x" xmlns:xacro="http://www.ros.org/wiki/xacro">

  <xacro:property name="base_length" value="0.45"/>
  <xacro:property name="base_width" value="0.32"/>
  <xacro:property name="base_height" value="0.12"/>
  <xacro:property name="wheel_radius" value="0.06"/>
  <xacro:property name="wheel_width" value="0.04"/>
  <xacro:property name="caster_radius" value="0.03"/>

  <material name="blue">
    <color rgba="0.1 0.3 0.8 1.0"/>
  </material>

  <material name="black">
    <color rgba="0.1 0.1 0.1 1.0"/>
  </material>

  <material name="gray">
    <color rgba="0.6 0.6 0.6 1.0"/>
  </material>

  <link name="base_link">
    <visual>
      <origin xyz="0 0 ${base_height/2}" rpy="0 0 0"/>
      <geometry>
        <box size="${base_length} ${base_width} ${base_height}"/>
      </geometry>
      <material name="blue"/>
    </visual>

    <collision>
      <origin xyz="0 0 ${base_height/2}" rpy="0 0 0"/>
      <geometry>
        <box size="${base_length} ${base_width} ${base_height}"/>
      </geometry>
    </collision>

    <inertial>
      <origin xyz="0 0 ${base_height/2}" rpy="0 0 0"/>
      <mass value="8.0"/>
      <inertia ixx="0.15" ixy="0.0" ixz="0.0"
               iyy="0.20" iyz="0.0"
               izz="0.25"/>
    </inertial>
  </link>

  <link name="left_wheel_link">
    <visual>
      <origin xyz="0 0 0" rpy="1.5708 0 0"/>
      <geometry>
        <cylinder radius="${wheel_radius}" length="${wheel_width}"/>
      </geometry>
      <material name="black"/>
    </visual>

    <collision>
      <origin xyz="0 0 0" rpy="1.5708 0 0"/>
      <geometry>
        <cylinder radius="${wheel_radius}" length="${wheel_width}"/>
      </geometry>
    </collision>

    <inertial>
      <mass value="0.8"/>
      <inertia ixx="0.001" ixy="0.0" ixz="0.0"
               iyy="0.001" iyz="0.0"
               izz="0.001"/>
    </inertial>
  </link>

  <joint name="left_wheel_joint" type="continuous">
    <parent link="base_link"/>
    <child link="left_wheel_link"/>
    <origin xyz="0 0.18 ${wheel_radius}" rpy="0 0 0"/>
    <axis xyz="0 1 0"/>
  </joint>

  <link name="right_wheel_link">
    <visual>
      <origin xyz="0 0 0" rpy="1.5708 0 0"/>
      <geometry>
        <cylinder radius="${wheel_radius}" length="${wheel_width}"/>
      </geometry>
      <material name="black"/>
    </visual>

    <collision>
      <origin xyz="0 0 0" rpy="1.5708 0 0"/>
      <geometry>
        <cylinder radius="${wheel_radius}" length="${wheel_width}"/>
      </geometry>
    </collision>

    <inertial>
      <mass value="0.8"/>
      <inertia ixx="0.001" ixy="0.0" ixz="0.0"
               iyy="0.001" iyz="0.0"
               izz="0.001"/>
    </inertial>
  </link>

  <joint name="right_wheel_joint" type="continuous">
    <parent link="base_link"/>
    <child link="right_wheel_link"/>
    <origin xyz="0 -0.18 ${wheel_radius}" rpy="0 0 0"/>
    <axis xyz="0 1 0"/>
  </joint>

  <link name="caster_link">
    <visual>
      <origin xyz="0 0 0" rpy="0 0 0"/>
      <geometry>
        <sphere radius="${caster_radius}"/>
      </geometry>
      <material name="gray"/>
    </visual>

    <collision>
      <origin xyz="0 0 0" rpy="0 0 0"/>
      <geometry>
        <sphere radius="${caster_radius}"/>
      </geometry>
    </collision>

    <inertial>
      <mass value="0.3"/>
      <inertia ixx="0.0002" ixy="0.0" ixz="0.0"
               iyy="0.0002" iyz="0.0"
               izz="0.0002"/>
    </inertial>
  </link>

  <joint name="caster_joint" type="fixed">
    <parent link="base_link"/>
    <child link="caster_link"/>
    <origin xyz="-0.16 0 ${caster_radius}" rpy="0 0 0"/>
  </joint>

  <link name="lidar_link">
    <visual>
      <origin xyz="0 0 0" rpy="0 0 0"/>
      <geometry>
        <cylinder radius="0.04" length="0.05"/>
      </geometry>
      <material name="gray"/>
    </visual>

    <collision>
      <origin xyz="0 0 0" rpy="0 0 0"/>
      <geometry>
        <cylinder radius="0.04" length="0.05"/>
      </geometry>
    </collision>

    <inertial>
      <mass value="0.2"/>
      <inertia ixx="0.0001" ixy="0.0" ixz="0.0"
               iyy="0.0001" iyz="0.0"
               izz="0.0001"/>
    </inertial>
  </link>

  <joint name="lidar_joint" type="fixed">
    <parent link="base_link"/>
    <child link="lidar_link"/>
    <origin xyz="0.12 0 ${base_height + 0.03}" rpy="0 0 0"/>
  </joint>

    <gazebo>
    <plugin
      filename="gz-sim-diff-drive-system"
      name="gz::sim::systems::DiffDrive">
      <left_joint>left_wheel_joint</left_joint>
      <right_joint>right_wheel_joint</right_joint>
      <wheel_separation>0.36</wheel_separation>
      <wheel_radius>0.06</wheel_radius>
      <topic>cmd_vel</topic>
      <odom_topic>odom</odom_topic>
      <tf_topic>tf</tf_topic>
      <frame_id>odom</frame_id>
      <child_frame_id>base_link</child_frame_id>
    </plugin>
  </gazebo>
      <gazebo reference="lidar_link">
    <sensor name="lidar_sensor" type="gpu_lidar">
      <always_on>true</always_on>
      <visualize>true</visualize>
      <update_rate>10</update_rate>
      <topic>scan</topic>
      <gz_frame_id>lidar_link</gz_frame_id>
      <lidar>
        <scan>
          <horizontal>
            <samples>360</samples>
            <resolution>1</resolution>
            <min_angle>-3.14159</min_angle>
            <max_angle>3.14159</max_angle>
          </horizontal>
        </scan>
        <range>
          <min>0.12</min>
          <max>8.0</max>
          <resolution>0.01</resolution>
        </range>
      </lidar>
    </sensor>
  </gazebo>

</robot>